Workbook

Sheet Tóm tắt
A1: TransVidCloud — Báo cáo kế hoạch hành động
A2: Bảng hạng mục công việc phải làm theo kế hoạch đã sửa (A01–A13): mỗi hạng mục có minh giải vị trí trong kiến trúc hệ thống, ước tính nỗ lực (person-day) và người chịu trách nhiệm.
A4: KẾ HOẠCH HIỆN HÀNH (bảng 3.2 — bản sửa 27/10)
A5: Hạng mục cấp kế hoạch (EPIC A01–A13) | D5: =COUNTIF('Hạng mục công việc'!$C$4:$C$94,"EPIC")
A6: Nhiệm vụ chi tiết bóc từ các hạng mục | D6: =COUNTIF('Hạng mục công việc'!$C$4:$C$94,"TASK")
A7: Dòng P1 / tùy chọn (ngoài tổng) | D7: =COUNTIF('Hạng mục công việc'!$C$4:$C$94,"P1")
A8: TỔNG EFFORT KẾ HOẠCH (pd) | D8: =SUMIFS('Hạng mục công việc'!$N$4:$N$94,'Hạng mục công việc'!$C$4:$C$94,"EPIC")
A9: Effort P1 / tùy chọn (pd, không tính vào tổng) | D9: =SUMIFS('Hạng mục công việc'!$N$4:$N$94,'Hạng mục công việc'!$C$4:$C$94,"P1")
A10: Hạng mục High (bắt buộc, nằm trên đường găng) | D10: =COUNTIFS('Hạng mục công việc'!$C$4:$C$94,"EPIC",'Hạng mục công việc'!$M$4:$M$94,"High")
A11: Hạng mục Medium (nên làm nếu còn capacity) | D11: =COUNTIFS('Hạng mục công việc'!$C$4:$C$94,"EPIC",'Hạng mục công việc'!$M$4:$M$94,"Medium")
A13: CÂN ĐỐI VỚI CAPACITY (4 người × 2,5 ngày × 4 tuần = 40 pd)
A14: Capacity sử dụng theo kế hoạch (pd) | D14: 40
A15: Capacity khi cả nhóm làm 3 ngày/tuần (pd) | D15: 48
A16: Tổng kế hoạch từ cột Effort (pd) | D16: =SUMIFS('Hạng mục công việc'!$N$4:$N$94,'Hạng mục công việc'!$C$4:$C$94,"EPIC")
A17: Tỷ lệ so với capacity kế hoạch | D17: =$D$16/$D$14
A18: Đệm còn lại cho rủi ro (pd) | D18: =$D$14-$D$16
A19: Tải nếu làm hết phần P1/tùy chọn (pd) | D19: =$D$16+$D$9
A20: Effort trung bình mỗi người (pd, 4 người) | D20: =$D$16/4
A21: Tải trung bình mỗi sprint (pd, 4 sprint) | D21: =$D$16/4
A22: Tỷ lệ nếu làm hết P1 so với capacity 3 ngày/tuần | D22: =($D$16+$D$9)/$D$15
A24: TẢI THEO SPRINT (ô cột E là % capacity; chi tiết ở sheet 'Cơ sở kế hoạch')
A25: Sprint 1 — pd phân bổ | D25: ='Cơ sở kế hoạch'!E35 | E25: ='Cơ sở kế hoạch'!E38
A26: Sprint 2 — pd phân bổ | D26: ='Cơ sở kế hoạch'!F35 | E26: ='Cơ sở kế hoạch'!F38
A27: Sprint 3 — pd phân bổ | D27: ='Cơ sở kế hoạch'!G35 | E27: ='Cơ sở kế hoạch'!G38
A28: Sprint 4 — pd phân bổ | D28: ='Cơ sở kế hoạch'!H35 | E28: ='Cơ sở kế hoạch'!H38
A29: Dự phòng — pd phân bổ | D29: ='Cơ sở kế hoạch'!I35 | E29: ='Cơ sở kế hoạch'!I38
A31: TRẠNG THÁI THEO BẰNG CHỨNG TRONG REPO
A32: Nhiệm vụ đã xong (✅ có bằng chứng) | D32: =COUNTIF('Hạng mục công việc'!$Q$4:$Q$94,"✅*")
A33: Đang làm / có khung / còn DRAFT (⭕) | D33: =COUNTIF('Hạng mục công việc'!$Q$4:$Q$94,"⭕*")
A34: Chưa có trong repo (❌) | D34: =COUNTIF('Hạng mục công việc'!$Q$4:$Q$94,"❌*")
A35: Chưa tới hạn / ngoài cam kết (⚪, ⛔) | D35: =COUNTIF('Hạng mục công việc'!$Q$4:$Q$94,"⚪*")+COUNTIF('Hạng mục công việc'!$Q$4:$Q$94,"⛔*")
A37: Đọc nhanh: 36 pd = 90% capacity 40 pd, mỗi người đúng 9,0/10,0 pd — cân đối theo người là tốt, nhưng phân bổ theo sprint dồn ~13 pd vào sprint 2 (capacity 10 pd) và chỉ còn ~4 pd đệm cho rủi ro backend (A02). Đường găng: A01 → A02/A03 → A10 → A13, song song là chuỗi cloud A07 → A08 → A06 → A09. Sáu điểm cần rà nằm ở sheet 'Mốc và phụ thuộc'.

Sheet Hạng mục công việc
A1: BẢNG HẠNG MỤC CÔNG VIỆC PHẢI LÀM (ACTION PLAN) — TransVidCloud · kế hoạch A01–A13
A2: 13 hạng mục, tổng 36 pd (chưa tính 3,5 pd P1/tùy chọn), bóc thành nhiệm vụ chi tiết · cột 'Kiến trúc liên quan [n]' tham chiếu bảng 15 giao diện của mục kiến trúc triển khai · cột 'Minh giải' đặt từng hạng mục vào vị trí kiến trúc và nêu ảnh hưởng khi nó thay đổi · effort là person-day tính cho phần việc còn lại (hiện trạng repo rà soát 27/10), chỉ ghi ở cấp hạng mục để không trùng lặp với nhiệm vụ
A3: STT | B3: Mã | C3: Cấp | D3: Công việc / hạng mục | E3: Kiến trúc liên quan [n] | F3: Nội dung / tiêu chí hoàn thành | G3: Tầng kiến trúc | H3: Thành phần / dịch vụ liên quan | I3: Module chức năng (SRS §26) | J3: Minh giải: vị trí và ảnh hưởng trong kiến trúc | K3: Hợp đồng / nguồn sự thật | L3: Sprint | M3: Ưu tiên | N3: Effort còn lại (pd) | O3: Người chịu trách nhiệm | P3: Phối hợp | Q3: Trạng thái (bằng chứng trong repo) | R3: Phụ thuộc / rủi ro | S3: Nguồn tài liệu
A4: 1 | B4: A01 | C4: EPIC | D4: Chốt kiến trúc và khung dự án | E4: Toàn bộ kiến trúc | F4: Bỏ nhãn DRAFT cho 6 file trong docs/contracts/ + openapi.yaml đủ endpoint luồng chính; khung backend/ (Spring Boot) và worker/ (Go) build + test được trên máy cá nhân; bàn giao cổng/env/lệnh build cho nhóm Cloud. Xong khi: cả 4 người review qua PR, thay đổi sau đó gắn nhãn contract-change. | G4: Ngang hệ thống | H4: docs/contracts/; backend/; worker/; docs/report (hình kiến trúc) | I4: A,B,C,D,E,F,G,H | J4: Hợp đồng tích hợp là đường biên cứng giữa tầng Ứng dụng (Spring Boot), tầng Xử lý (Go + FFmpeg) và tầng Dữ liệu (S3/SQS/DynamoDB): cùng một message job, cùng một item videos. Đổi ở đây kéo theo đồng thời code backend, code worker, local init và Terraform — nên phải chốt trước khi bốn nhánh chạy song song, nếu không mỗi nhánh tự định nghĩa một sự thật. | K4: video-state-machine.md, sqs-job-message.schema.json, s3-key-convention.md, dynamodb-tables.md, upload-limits.md, openapi.yaml | L4: 1 | M4: High | N4: 2 | O4: Cả nhóm (điều phối: Phương) | P4: Lưu, Nguyên | Q4: ⭕ 6 file hợp đồng đều còn nhãn DRAFT; worker/ đã có khung 9 package; backend/ mới chỉ có README | R4: Là gate của mọi hạng mục còn lại: A02–A09 viết trên nền nháp nếu chưa chốt | S4: Progress 2 §3.2 dòng A01; introduction/1 §4.A1; docs-common/2, docs-common/3
A5: 2 | B5: A01.1 | C5: TASK | D5: Chốt 5 file hợp đồng nghiệp vụ | F5: Cả 4 người review: state machine, message SQS, key S3, bảng DynamoDB, giới hạn upload. Thay đổi sau đó phải qua PR nhãn contract-change. | G5: Ngang hệ thống | H5: docs/contracts/; ranh giới API vs Worker | I5: A,B,C,D,E,F | J5: Đây là văn bản định nghĩa ai được chuyển trạng thái nào: API chỉ UPLOADING→PENDING, Worker chỉ PROCESSING→COMPLETED/FAILED_*. Nếu không chốt, hai phía sẽ tự định nghĩa trạng thái và mất nguồn sự thật DynamoDB. | K5: docs/contracts/*.md (5 file) | L5: 1 | M5: High | O5: Phương | P5: Vũ, Lưu, Nguyên | Q5: ⭕ DRAFT; worker/Week1 mục 5 ghi đã review ngày 1 | R5: docs-common/3: lệch contract phải sửa code hoặc mở PR, không 'sửa lặng' một phía | S5: docs-common/3. Contracts and boundaries.md §3.1, §3.4
A6: 3 | B6: A01.2 | C6: TASK | D6: Hoàn thiện openapi.yaml đủ endpoint luồng chính | F6: Schema request/response đầy đủ cho auth, project, video, confirm; frontend sinh mock từ file này. | G6: Ứng dụng/API + Trình bày | H6: Spring Boot REST; mock layer frontend (MSW) | I6: A,B,C,F | J6: openapi.yaml vừa là spec của tầng Ứng dụng vừa là đầu vào trực tiếp của tầng Trình bày: frontend xây mock API từ nó để không chờ backend. Endpoint thiếu nghĩa là UI phải tự bịa giả định. | K6: openapi.yaml | L6: 1 | M6: High | O6: Phương | P6: Vũ (mock) | Q6: ⭕ DRAFT, chưa có schema request/response đầy đủ | R6: Frontend cần sớm nhất có thể (trước cả khi backend có code) | S6: docs-common/2 §2.2; docs-frontend/2. Timelines.md §3
A7: 4 | B7: A01.3 | C7: TASK | D7: Dựng khung backend Spring Boot + bàn giao cổng/env/health | F7: Khung chạy ở máy cá nhân, ghi rõ cổng 8080, biến môi trường, health endpoint để Lưu viết Dockerfile. | G7: Ứng dụng/API | H7: backend/ Spring Boot trên EC2; cấu hình runtime từ env/SSM | I7: A,B,C,D | J7: Là chỗ đặt toàn bộ module A-F của tầng Ứng dụng. App không hard-code bucket/queue ARN mà đọc tên từ env/SSM do Cloud cấp - đó là điều kiện để cùng một Docker image chạy cả local và AWS. | K7: .env.example; docs-backend/04 | L7: 1 | M7: High | O7: Phương | P7: Lưu (Dockerfile) | Q7: ❌ Chưa có: backend/ chỉ có README, chưa pom.xml | R7: Chặn C0.2 Dockerfile backend và M2 | S7: docs-common/2 §2.2 'Ứng dụng'; rà soát repo 21/10/2026
A8: 5 | B8: A01.4 | C8: TASK | D8: Dựng khung worker Go theo cấu trúc 9 package | F8: cmd/worker + internal/{config,consumer,validate,transcode,storage,state,job,shutdown,logging}; gửi bàn giao build/run/env/IAM cho Lưu và Nguyên. | G8: Xử lý | H8: worker/ Go; container tvc-worker trong EC2 ASG | I8: E | J8: Module job là nơi duy nhất biết thứ tự các bước, các package còn lại là thư viện thuần mock được (SQS/S3/DynamoDB đều là interface). Nhờ vậy worker không có nhánh code theo môi trường: mọi khác biệt local/cloud nằm ở biến môi trường. | K8: docs-worker/3 §3.2, §3.8, §3.9 | L8: 1 | M8: High | O8: Vũ | Q8: ✅ Có code (1.427 dòng Go, 9 package, go test xanh); ⭕ bàn giao mục 6.1 chưa gửi | R8: Bàn giao trễ chặn Dockerfile (C0.2) và policy IAM (C2.1) | S8: docs-worker/work/Week1.md §3 ngày 3, §6.1; rà soát repo 27/10
A9: 6 | B9: A02 | C9: EPIC | D9: Backend Auth, Project, Video | E9: [1], [3], [5] | F9: Đăng ký/đăng nhập JWT; API key theo project (lưu hash) + lớp xác thực Developer API; CRUD project; danh sách video theo project (cursor pagination); kiểm tra quyền sở hữu mọi truy cập; CORS cấu hình qua biến môi trường. Xong khi: SaaS và Developer API gọi vào cùng bộ module, không có nhánh code riêng. | G9: Ứng dụng / API | H9: Spring Boot (module A, B, F) trên EC2 → DynamoDB | I9: A,B,F | J9: Toàn bộ module A/B/F nằm trong một tiến trình Spring Boot — hiện thực hóa nguyên tắc 'một backend, hai cách dùng': SaaS Web và Developer API chỉ khác nhau ở lớp xác thực ([3]), phía sau dùng chung metadata và quyền sở hữu. Vì UI ([1]) và luồng upload ([4]) đều gọi vào đây, chậm A02 là chậm cả frontend lẫn e2e. | K9: openapi.yaml; dynamodb-tables.md; docs-common/3 §3.2 (ownership) | L9: 1–2 | M9: High | N9: 5 | O9: Phương | P9: Vũ (lease/quyền sở hữu), Lưu (SG, compose) | Q9: ❌ backend/ chỉ có README — chưa một dòng code; đây là hạng mục lớn nhất và nằm trên đường găng | R9: Không cắt được (lever cuối): không có backend thì e2e, demo và số liệu thực nghiệm đều vô nghĩa | S9: Progress 2 §3.2 dòng A02, §3.3; docs-backend/11-plan-and-timeline.md
A10: 7 | B10: A02.1 | C10: TASK | D10: Đăng ký / đăng nhập JWT | F10: POST /auth/register, POST /auth/login trả JWT; email duy nhất (giao dịch ghi hai item). | G10: Ứng dụng/API | H10: Spring Boot module A; bảng users | I10: A | J10: JWT là lớp xác thực của SaaS Web; không có thì F2 đăng nhập và guard route của frontend chỉ tồn tại trên mock, không hợp nhất được ở tuần 9. | K10: openapi.yaml; dynamodb-tables.md | L10: 1–2 | M10: High | O10: Phương | Q10: ❌ Chưa có | R10: ADR 0001: email duy nhất cần giao dịch ghi hai item vì DynamoDB không có unique constraint | S10: docs-common/5 ADR 0001; Progress 2 §1.2.1
A11: 8 | B11: A02.2 | C11: TASK | D11: API key theo project (lưu hash) + xác thực API key | F11: POST /projects/{id}/api-keys; chỉ lưu hash trong bảng apikeys; middleware xác thực máy-máy. | G11: Ứng dụng/API | H11: Spring Boot module A; bảng apikeys | I11: A,F | J11: API key gắn project chứ không gắn user, tạo phạm vi thu hồi rõ - đây chính là điểm biến TransVidCloud thành lớp 'Developer Platform': hệ thống bên ngoài gọi được toàn bộ pipeline mà không biết tới AWS. Cắt cuối cùng vì là điểm khác biệt của Developer API. | K11: openapi.yaml; dynamodb-tables.md | L11: 1–2 | M11: High | O11: Phương | Q11: ❌ Chưa có | R11: Timeline §7 xếp JWT trước, API key sau khi cắt giảm | S11: Progress 2 §1.3.3; introduction/1 §7 mục 6
A12: 9 | B12: A02.3 | C12: TASK | D12: CRUD project | F12: Tạo/list project; mỗi user chỉ thấy project của mình. | G12: Ứng dụng/API + Dữ liệu | H12: Spring Boot module A; bảng projects (GSI) | I12: A | J12: Project là không gian làm việc và cũng là tiền tố của mọi S3 key ({projectId}/{videoId}/...): nó đồng thời là đơn vị phân quyền và đơn vị bố trí dữ liệu trong bucket. | K12: dynamodb-tables.md; s3-key-convention.md | L12: 1–2 | M12: High | O12: Phương | Q12: ❌ Chưa có | R12: Frontend F2.3 cần endpoint này để hợp nhất | S12: docs-frontend/2 §3
A13: 10 | B13: A02.4 | C13: TASK | D13: Danh sách video theo project (cursor pagination) | F13: GET /projects/{projectId}/videos, phân trang cursor. | G13: Ứng dụng/API + Dữ liệu | H13: Spring Boot module B; GSI videos trên projectId | I13: B | J13: Truy vấn theo project là access pattern cố định đã thiết kế key/GSI cho DynamoDB; không có RDS nên mọi pagination phải làm bằng cursor trên khoá chính/GSI. | K13: dynamodb-tables.md | L13: 1–2 | M13: High | O13: Phương | P13: Vũ (UI F4) | Q13: ❌ Chưa có | S13: docs-common/1 §1.3; docs-backend/06
A14: 11 | B14: A02.5 | C14: TASK | D14: Phân quyền ownership | F14: Từ chối truy cập tài nguyên không thuộc user/project của mình. | G14: Ứng dụng/API + Bảo mật | H14: Spring Boot module A; IAM là lớp hạ tầng riêng | I14: A | J14: Ownership là kiểm soát ở tầng ứng dụng, độc lập với IAM role: IAM chỉ giới hạn AWS principle truy cập dịch vụ, không phân biệt người dùng cuối. Checklist A8 yêu cầu kiểm chứng 'người dùng không đọc project của người khác'. | K14: docs-backend/07-security-and-authorization.md | L14: 1–2 | M14: High | O14: Phương | P14: Lưu (ca test A8) | Q14: ❌ Chưa có | S14: docs-cloud/4 §9; docs-backend/07
A15: 12 | B15: A02.6 | C15: TASK | D15: CORS cấu hình qua biến môi trường | F15: Chỉ bật khi frontend và API khác origin; dùng cho presigned PUT và CloudFront /api/*. | G15: Ứng dụng/API + Edge | H15: Spring Boot; bucket input CORS; CloudFront behavior | I15: A,C | J15: Lớp CORS chỉ lộ ra khi đổi phương án truy cập (mục 8.1: bỏ /api/* khỏi CloudFront, tách app.<domain> và api.<domain>). Nếu giữ một entry CloudFront thì không cần, nên để cấu hình env chứ không hard-code. | K15: docs-backend/05; introduction/1 §8.1 | L15: 1–2 | M15: High | O15: Phương | P15: Nguyên (C4) | Q15: ❌ Chưa có | R15: Chỉ cần cho phương án dự phòng hai domain | S15: introduction/1 §8.1; docs-frontend/2 §3
A16: 13 | B16: A03 | C16: EPIC | D16: Upload và điều phối job | E16: [4], [5], [6], [9] | F16: POST /projects/{id}/videos (khai báo + presigned PUT, chặn 413/422 theo upload-limits); POST /videos/{id}/confirm (HeadObject → PENDING → SendMessage); GET /videos/{id} trả trạng thái + assets + link streaming; chống mất job giữa ghi trạng thái và gửi message. Xong khi: một video thật đi từ khai báo tới PENDING rồi COMPLETED. | G16: Ứng dụng / API + Dữ liệu | H16: Spring Boot module C, D → S3 input, SQS jobs, DynamoDB videos | I16: C,D | J16: Đây là chỗ tầng Ứng dụng giao với tầng Xử lý: S3 input [4], DynamoDB [5], SQS [6] và máy trạng thái [9]. UpdateItem và SendMessage không nguyên tử, nên thứ tự ghi + cơ chế phục hồi (reconcile/lease) là quyết định kiến trúc, không phải chi tiết triển khai — sai ở đây tạo video treo ở PENDING mãi mãi. | K16: upload-limits.md; sqs-job-message.schema.json; video-state-machine.md | L16: 2–3 | M16: High | N16: 2.5 | O16: Phương | P16: Vũ (worker), Nguyên (CORS bucket, quyền SQS) | Q16: ❌ Chưa có code; thứ tự xác nhận input (HeadObject) và cơ chế chống mất job chưa chốt trong hợp đồng | R16: Phụ thuộc A01 (schema) và A08 (bucket/queue); là tiền đề trực tiếp của A10 | S16: Progress 2 §3.2 dòng A03; docs-common/3 §3.3; docs-cloud/3 §10 (điểm mở)
A17: 14 | B17: A03.1 | C17: TASK | D17: POST /projects/{id}/videos: kiểm tra khai báo + ký presigned URL | F17: Client khai báo sizeBytes, contentType; từ chối nếu vượt 200 MB / định dạng; ký PUT 15 phút kèm Content-Length đã khai báo (cần thử để chắc S3 từ chối file sai kích thước). | G17: Ứng dụng/API + Dữ liệu | H17: Spring Boot module C; S3 input presigned PUT | I17: C | J17: Presigned PUT bản thân nó không giới hạn kích thước, nên lớp bảo vệ phải xếp tầng: client (UX) → API từ chối khai báo → confirm kiểm HeadObject → worker ffprobe → lifecycle S3 dọn file. Bỏ một tầng là thủng giới hạn. | K17: upload-limits.md; s3-key-convention.md | L17: 2–3 | M17: High | O17: Phương | P17: Lưu (CORS input) | Q17: ❌ Chưa có | R17: Chưa kiểm chứng S3 enforced Content-Length trên AWS | S17: introduction/1 §8.2; docs-cloud/3 §5.1
A18: 15 | B18: A03.2 | C18: TASK | D18: POST /videos/{id}/confirm: HeadObject → PENDING → SendMessage | F18: Kiểm tra object tồn tại và đúng dung lượng, chuyển UPLOADING→PENDING, gửi message SQS theo schemaVersion 1. | G18: Ứng dụng/API + Dữ liệu | H18: Spring Boot module D; SQS producer; DynamoDB | I18: C,D | J18: Là điểm hai tầng gặp nhau: một item DynamoDB và một message SQS. Ghi DynamoDB và gửi SQS KHÔNG phải một giao dịch nguyên tử, nên đây là chỗ dễ mất job nhất của toàn kiến trúc - phải chốt cơ chế chống mất trước khi test A5/A8. | K18: sqs-job-message.schema.json; video-state-machine.md | L18: 2–3 | M18: High | O18: Phương | P18: Vũ (quyền sở hữu job) | Q18: ❌ Chưa có | R18: Điểm mở ghi ở docs-cloud/3 §10, hạn M2 | S18: docs-cloud/3 §5.2, §10; docs-common/3 §3.5
A19: 16 | B19: A03.3 | C19: TASK | D19: GET /videos/{id}: trạng thái, assets, link streaming | F19: Trả trạng thái + errorCode + assets; API ghép tiền tố /media/ cho link phát. | G19: Ứng dụng/API + Edge | H19: Spring Boot module F; DynamoDB assets map; CloudFront /media/* | I19: B,F | J19: 'Một call cho trạng thái + asset' là quyết định kiến trúc để vòng poll của bên tích hợp đơn giản và rẻ. Assets lưu S3 key chứ không lưu URL đầy đủ; URL cuối cùng do tầng Edge ghép (/media/), nhờ đó đổi domain/CDN không phải ghi lại dữ liệu. | K19: openapi.yaml; s3-key-convention.md; docs-worker/5 | L19: 2–3 | M19: High | O19: Phương | P19: Vũ (F5 player) | Q19: ❌ Chưa có | R19: Quy ước 'key vs URL' nằm trong nhóm dễ lệch tích hợp | S19: Progress 2 §1.3.2; docs-common/3 §3.5
A20: 17 | B20: A03.4 | C20: TASK | D20: Kiểm chứng 'Xong khi' của A3 | F20: Upload file 201 MB bị API từ chối; file hợp lệ vào queue và worker nhận được. | G20: Ứng dụng/API + Xử lý | H20: API + S3 input + SQS jobs | I20: C,D | J20: Là phép thử nối tầng Ứng dụng với tầng Xử lý qua hàng đợi: nếu message vào queue đúng schema thì worker kiểm chứng độc lập được ngay cả khi phần UI chưa xong. | K20: docs/contracts/upload-limits.md | L20: 2–3 | M20: High | O20: Phương | P20: Vũ, Lưu (e2e A8.1) | Q20: ❌ Chưa có | S20: introduction/1 §4.A3
A21: 18 | B21: A03.5 | C21: TASK | D21: Chống mất job ở confirm→SQS + lease/quyền sở hữu | F21: Thống nhất cơ chế (ví dụ gửi SQS lại khi PENDING không có job, hoặc lease/attemptCount) để không mất việc im lặng và không hai worker cùng xử lý. | G21: Ứng dụng/API + Xử lý | H21: API module D; worker consumer; DynamoDB | I21: C,D,E | J21: Ba khoảng trống được ghi rõ là 'hạ tầng SQS tự nó không giải quyết được': UpdateItem và SendMessage không nguyên tử; điều kiện status<>COMPLETED chưa ngăn hai worker cùng xử lý; lease/reclaim khi worker chết chưa được hợp đồng hoá. | K21: docs-cloud/3 §5.2; docs-common/3 §3.5 | L21: 2–3 | M21: High | O21: Phương | P21: Vũ | Q21: ❌ Chưa chốt | R21: Người xử lý: Phương/Vũ, Cloud review - hạn M2 | S21: docs-cloud/3 §10
A22: 19 | B22: A04 | C22: EPIC | D22: Hoàn thiện Worker pipeline | E22: [7], [8], [9] | F22: Heartbeat gia hạn visibility ~120s; SIGTERM trả message sớm; DLQ sau 3 lần nhận; hoàn thiện chaos-kill-worker.sh; ghép Dockerfile + make up và chạy lại kịch bản e2e trên AWS thật tới COMPLETED. Xong khi: `make chaos` chứng minh job không mất. | G22: Xử lý | H22: Go worker (FFmpeg + ffprobe) trong EC2 ASG (Spot) — module E | I22: E | J22: Module E là nơi duy nhất chạy FFmpeg, tách hẳn tầng ứng dụng để workload CPU nặng không bao giờ chặn API. Worker chỉ chạm [7] compute, [8] S3 output và [9] state — không có quyền nào khác, nên blast radius của nó nhỏ có chủ đích. | K22: sqs-job-message.schema.json; s3-key-convention.md; video-state-machine.md | L22: 1–2 | M22: High | N22: 3 | O22: Vũ | P22: Phương (message/lease), Lưu (Dockerfile, make up) | Q22: ✅ Phần lớn đã xong, có bằng chứng: 1.427 dòng Go / 9 package, POC FFmpeg phát được qua hls.js, full path LocalStack COMPLETED 3555ms, idempotency skipped_completed, make test xanh; ❌ heartbeat/DLQ/chaos/Dockerfile chưa có | R22: 3 pd chỉ đúng nếu ghép Docker (A07) mượt; heartbeat trễ làm chaos test (A11) không có ý nghĩa | S22: Progress 2 §3.2 dòng A04; docs-worker/work/Week1.md §5–6; docs-worker/3 §3.3, §3.10
A23: 20 | B23: A04.1 | C23: TASK | D23: POC FFmpeg: 2 rendition + master playlist + thumbnail | F23: Một lần chạy sinh hls/360p + hls/720p + segment; master.m3u8 viết tay (RESOLUTION từ ffprobe); thumb -ss 1, fallback -ss 0. Bằng chứng: phát thật qua master playlist. | G23: Xử lý | H23: FFmpeg; đầu ra HLS phục vụ CloudFront /media/* | I23: E | J23: Định dạng đầu ra chính là hợp đồng với tầng Edge: master playlist tham chiếu playlist tương đối nên segment phải giữ đường dẫn tương đối, nếu không player nhận URL sai khi đi qua rewrite /media. | K23: docs-worker/3 §3.5 | L23: 1–2 | M23: High | O23: Vũ | Q23: ✅ Hoàn thành, có bằng chứng (hls.js: MANIFEST_PARSED 2 level, phát hết 9,17 s) | S23: docs-worker/work/Week1.md §3 ngày 2, §6
A24: 21 | B24: A04.2 | C24: TASK | D24: Tối ưu chi phí CPU: split, preset veryfast, không 1080p | F24: scale=-2:{360,720}, không upscale nguồn ≤ 360; timeout FFmpeg 15 phút → FAILED_TRANSCODE/FFMPEG_TIMEOUT. | G24: Xử lý | H24: FFmpeg trên máy 2 vCPU (Spot) | I24: E | J24: Lựa chọn này là biến chi phí của kiến trúc: giảm số lần giải mã quyết định số vCPU cần cho một job, từ đó quyết định loại máy Spot, chi phí benchmark và thời gian cold start. 1080p hạ xuống P1 để giữ cân đối tải. | K24: docs-worker/3 §3.5; upload-limits.md | L24: 1–2 | M24: High | O24: Vũ | Q24: ✅ Hoàn thành (bằng chứng: nguồn 640x360 ra 2 rendition 640x360, exit 0) | S24: docs-worker/work/Week1.md §6; docs-common/1 §1.6
A25: 22 | B25: A04.3 | C25: TASK | D25: ffprobe validate → FAILED_VALIDATION | F25: Bốn kiểm: NOT_A_VIDEO, CODEC_UNSUPPORTED, DURATION_EXCEEDED, HEIGHT_EXCEEDED; validate fail thì ACK message, không retry. | G25: Xử lý + Dữ liệu | H25: worker internal/validate; DynamoDB status | I25: E,D | J25: Là lớp kiểm tra cuối của chuỗi bảo vệ giới hạn upload và là chỗ phân nhánh ngữ nghĩa của state machine: lỗi nghiệp vụ thì ACK ngay, lỗi hệ thống thì để SQS retry - phân biệt sai sẽ gây retry vô nghĩa hoặc DLQ đầy. | K25: upload-limits.md; video-state-machine.md | L25: 1–2 | M25: High | O25: Vũ | P25: Phương | Q25: ✅ Hoàn thành, chặn đúng 4 ca (301 s / 1440p / file giả / không audio) | R25: Danh sách codec còn chờ chốt trong A1 | S25: docs-worker/3 §3.4; Week1 §6 ngày 2
A26: 23 | B26: A04.4 | C26: TASK | D26: Consumer SQS + storage S3 + state DynamoDB + cleanup | F26: ReceiveMessage long polling 20 s; upload trước khi ghi COMPLETED; UpdateItem ConditionExpression status<>COMPLETED; Content-Type đúng cho .m3u8/.ts/.jpg; defer cleanup + quét thư mục mồ côi lúc boot. | G26: Xử lý + Dữ liệu | H26: worker internal/{consumer,storage,state,job}; S3 2 bucket; DynamoDB | I26: E,B,D | J26: Thứ tự 'upload đủ object rồi mới ghi COMPLETED rồi mới ACK' là bất biến đúng đắn của toàn pipeline: nếu đảo, API sẽ trả link tới asset chưa tồn tại. Conditional write là cơ chế chống hai worker ghi đè lên kết quả đã hoàn tất. | K26: s3-key-convention.md; dynamodb-tables.md; docs-worker/5 | L26: 1–2 | M26: High | O26: Vũ | Q26: ✅ Hoàn thành trên LocalStack (job_finished COMPLETED 3555 ms, 8 object, attemptCount đúng) | R26: Chưa kiểm chứng trên AWS (M2) | S26: docs-worker/work/Week1.md §3 ngày 3, §6
A27: 24 | B27: A04.5 | C27: TASK | D27: Ghép Dockerfile + make up, chạy lại kịch bản e2e qua compose | F27: Image worker có ffmpeg+ffprobe trong PATH; chạy đủ chuỗi upload → COMPLETED qua nginx :8000. | G27: Xử lý + Hạ tầng | H27: container tvc-worker; docker-compose profile full; nginx edge | I27: E,G | J27: Là điểm hợp nhất nguyên tắc 'cùng code, khác cấu hình': chính image đã chạy local phải chạy được trên ECR/EC2, chỉ khác AWS_ENDPOINT_URL. Không có Dockerfile thì M1/M2 không có bằng chứng end-to-end. | K27: docs-common/1 §1.4; docker-compose.yml | L27: 1–2 | M27: High | O27: Vũ | P27: Lưu (C0.2) | Q27: ❌ Chưa có Dockerfile trong repo | R27: Bị chặn bởi C0.2; là tiêu chí 'Xong khi' của epic A4 | S27: docs-worker/4 §6.3; docs-cloud/4 §4.1
A28: 25 | B28: A04.6 | C28: TASK | D28: Heartbeat gia hạn visibility ~120 s | F28: Goroutine ChangeMessageVisibility đặt lại ~300 s mỗi 120 s trong lúc FFmpeg chạy; thử job dài hơn timeout ban đầu. | G28: Xử lý | H28: SQS ChangeMessageVisibility; worker internal/consumer | I28: E,D | J28: Visibility 300 s là cấu hình khởi điểm chứ không phải deadline transcode. Không heartbeat thì job dài sẽ bị nhận đôi - vi phạm quyền sở hữu job và làm hỏng mọi phép đo benchmark. | K28: docs-worker/3 §3.3 bước 4; docs-cloud/3 §5.2 | L28: 1–2 | M28: High | O28: Vũ | P28: Phương (lease/ownership) | Q28: ❌ Chưa làm - config TVC_HEARTBEAT_INTERVAL đã có nhưng consumer ghi rõ 'Heartbeat thuộc Sprint 2' | R28: Điểm mở cần chốt với A5.5 | S28: docs-worker/3 §3.8; code worker/internal/consumer/consumer.go
A29: 26 | B29: A04.7 | C29: TASK | D29: SIGTERM: ngừng poll, trả message, dọn file tạm | F29: Bắt SIGTERM/SIGINT → không ReceiveMessage mới → đặt visibility về ~30 s → bỏ upload dở → cleanup → exit 0. | G29: Xử lý + Hạ tầng | H29: worker internal/shutdown; EC2 Spot 2-min interruption; ASG | I29: E,G | J29: Spot chỉ báo trước ~2 phút trong khi một job 720p có thể lâu hơn, nên chiến lược 'trả message ngay' (không cố chạy nốt) là điều kiện để dùng Spot rẻ. ASG ScaleInProtectedInstances=Wait không thay thế được cơ chế này. | K29: docs-worker/3 §3.10; introduction/1 §8.3 | L29: 1–2 | M29: High | O29: Vũ | P29: Nguyên (Spot/ASG) | Q29: ⭕ internal/shutdown đã dừng vòng nhận và exit 0; chưa trả message về queue | R29: Phối hợp C3.3/C5.6 theo bảng đồng bộ Sprint 2-3 | S29: docs-worker/work/Week1.md §6 ngày 3; docs-worker/3 §3.10
A30: 27 | B30: A04.8 | C30: TASK | D30: Idempotency + phân loại FAILED_* + conditional write | F30: Video đã COMPLETED → bỏ qua, xóa message; không ghi đè COMPLETED; FAILED_VALIDATION ACK, FAILED_TRANSCODE/STORAGE để retry. | G30: Xử lý + Dữ liệu | H30: DynamoDB UpdateItem có điều kiện; SQS ACK | I30: E,D | J30: Là chốt an toàn duy nhất chống hai kết quả mâu thuẫn khi message được giao lại (at-least-once). Worker không có quyền sửa bảng user/project/apikey nên DynamoDB videos là nơi duy nhất nó ghi - thu nhỏ blast radius. | K30: video-state-machine.md; docs-common/3 §3.3 | L30: 1–2 | M30: High | O30: Vũ | Q30: ✅ Hoàn thành, có bằng chứng (skipped_completed, attemptCount không tăng) | S30: docs-worker/work/Week1.md §5, §6 ngày 3
A31: 28 | B31: A04.9 | C31: TASK | D31: DLQ sau 3 lần nhận + hoàn thiện chaos-kill-worker.sh | F31: Kill worker giữa job → job nhận lại và hoàn tất; lỗi lặp lại → message vào DLQ; ghi receive count và kết quả thực. | G31: Xử lý + Dữ liệu + Kiểm chứng | H31: SQS redrive (maxReceiveCount 3) + DLQ; local/scripts/chaos-kill-worker.sh | I31: E,D,H | J31: DLQ là bằng chứng vận hành của cả hai mục tiêu môn học (phục hồi lỗi và chi phí) - nếu không có phép thử này thì 'retry' chỉ là tuyên bố trong tài liệu. Init local đã đặt maxReceiveCount 3 nhưng chưa từng được kiểm chứng. | K31: docs-cloud/4 §5; docs-worker/3 §3.13 | L31: 1–2 | M31: High | O31: Vũ | P31: Lưu (chủ trì chaos) | Q31: ❌ make chaos vẫn in 'chưa triển khai' | R31: Hạn chế: chưa rõ ai đồng bộ trạng thái khi message vào DLQ - cần App chốt | S31: docs-common/2 §2.2; docs-cloud/3 §5.2
A32: 29 | B32: A05 | C32: EPIC | D32: Xây dựng giao diện người dùng | E32: [1], [2], [4], [10] | F32: Vite + React + TypeScript theo design token; đăng nhập + project; upload presigned có progress; danh sách video với badge đủ 7 trạng thái + polling; trình phát hls.js + link streaming. Xong khi: một người dùng thật upload và xem được video qua CloudFront. | G32: Trình bày | H32: React + Vite (hosting S3/CloudFront), hls.js, lớp mock MSW → API thật | I32: A,B,C,F (phía trình bày) | J32: Tầng trình bày nằm ngoài mọi boundary AWS: gọi [1] cho trang, [2] cho /api/* qua Tunnel, [4] PUT thẳng vào S3 (phần CORS không mock được) và [10] cho /media/* HLS. Vì vậy UI chỉ được nói chuyện với một interface duy nhất; đổi mock → real không được sửa logic UI. | K32: openapi.yaml; video-state-machine.md; docs/contracts/README.md | L32: 2–3 | M32: High | N32: 4 | O32: Vũ | P32: Phương (hợp đồng response), Lưu (hosting bucket frontend) | Q32: ❌ frontend/ chỉ có README; chiến lược mock-first (MSW + VITE_API_MODE) đã duyệt trong docs-frontend/work/Week1.md | R32: Trang embed/mã nhúng là lever cắt ~0,5 pd; hợp nhất mock ↔ real dồn cuối sprint 3 | S32: Progress 2 §3.2 dòng A05; docs-frontend/2 Timelines; docs-frontend/work/Week1.md
A33: 30 | B33: A05.1 | C33: TASK | D33: F1 Dựng khung project (Vite+React+TS, token, router) | F33: Dev server 5173 qua nginx :8000; áp variables.css (không hex trong JSX); sidebar 240 px + header 56 px; route /login, /projects, /projects/:id/videos, /videos/:id, /embed. | G33: Trình bày | H33: frontend/src; design token Frontend template | I33: F | J33: Tuân thủ Do's & Don'ts của design system là điều kiện để báo cáo trình bày UI nhất quán; mọi giá trị thị giác đi qua token nên đổi theme không đụng code. | K33: Frontend template/tokens.json; docs-frontend/4 | L33: 2–3 | M33: High | O33: Vũ | Q33: ❌ Chưa có | R33: Không phụ thuộc backend - làm ngay được | S33: docs-frontend/2 §1; docs-frontend/work/Week1.md
A34: 31 | B34: A05.2 | C34: TASK | D34: F2 Đăng nhập + project (kèm mock API layer MSW) | F34: Interface duy nhất cho auth/projects/videos sinh từ openapi.yaml; hai implementation mock/real chọn bằng VITE_API_MODE; fixture đủ 7 trạng thái; lỗi 401/413/422; route guard. | G34: Trình bày + Ứng dụng/API | H34: MSW handlers; Spring Boot module A (khi hợp nhất) | I34: F,A | J34: Mock layer trung thành với contract là cách frontend chạy độc lập mà vẫn không tự bịa API: giả định phải ghi vào 5. API Integration.md nhãn 'chờ Phương xác nhận', thiếu contract thì mở PR contract chứ không code chui. | K34: docs/contracts/openapi.yaml; docs-frontend/5 | L34: 2–3 | M34: High | O34: Vũ | P34: Phương (xác nhận giả định) | Q34: ❌ Chưa có | R34: Hợp nhất backend thật dự kiến tuần 9 | S34: docs-frontend/work/Week1.md buổi 2
A35: 32 | B35: A05.3 | C35: TASK | D35: F3 Upload bằng presigned URL | F35: Kiểm tra client ≤ 200 MB, mp4/mov/mkv/webm; khai báo sizeBytes/contentType → PUT bằng XMLHttpRequest để có progress → confirm; mock mô phỏng tự chuyển PENDING→COMPLETED. | G35: Trình bày + Dữ liệu | H35: S3 input presigned PUT; API module C; CORS | I35: F,C | J35: Kiểm tra phía client chỉ để UX, không phải lớp bảo vệ - nguồn sự thật là upload-limits.md ở API/worker. Đây cũng là nơi dễ lệch nhất khi hợp nhất: CORS, SignatureDoesNotMatch, Content-Length là những hành vi S3 thật không mock được. | K35: upload-limits.md; s3-key-convention.md | L35: 2–3 | M35: High | O35: Vũ | P35: Phương (A3.1), Lưu (CORS C1.2) | Q35: ❌ Chưa có | R35: Nợ kỹ thuật tuần 9: hành vi S3 thật | S35: docs-frontend/work/Week1.md buổi 3; §4
A36: 33 | B36: A05.4 | C36: TASK | D36: F4 Danh sách video + trạng thái (polling) | F36: Danh sách theo project, badge theo state machine; poll GET /videos/{id} mỗi 3-5 s khi PENDING/PROCESSING. | G36: Trình bày + Ứng dụng/API | H36: API module B (A2.4, A3.3) | I36: F,B | J36: UI phản ánh trực tiếp state machine dùng chung với worker; vì MVP không có webhook nên polling là cơ chế duy nhất đưa trạng thái từ tầng Xử lý về người dùng. | K36: video-state-machine.md | L36: 2–3 | M36: High | O36: Vũ | Q36: ❌ Chưa có | R36: A7 webhook (P1) sẽ thay polling nếu làm | S36: docs-frontend/2 §1; Progress 2 §1.2.3
A37: 34 | B37: A05.5 | C37: TASK | D37: F5 Trình phát HLS + link streaming + mã nhúng | F37: hls.js phát master playlist khi COMPLETED; copy link streaming; iframe embed. | G37: Trình bày + Edge | H37: hls.js; CloudFront /media/* → bucket output | I37: F | J37: Player là điểm cuối của chuỗi phân phối: nó chỉ hoạt động khi rewrite /media và OAC ở tầng Edge đúng, đồng thời Content-Type và đường dẫn tương đối của segment do worker (A4.1) quyết định. | K37: docs-frontend/3; docs-cloud/3 §7 | L37: 2–3 | M37: High | O37: Vũ | P37: Nguyên (C4), Vũ (A4) | Q37: ❌ Chưa có | R37: Thứ tự cắt A6: bỏ đoạn mã nhúng trước, giữ player + link | S37: docs-frontend/2 §4; introduction/1 §7 mục 3
A38: 35 | B38: A06 | C38: EPIC | D38: IAM và bảo mật | E38: [5], [6], [8], [9], [12] | F38: Policy cho API role / Worker role / Deploy role theo least-privilege; instance profile cho EC2; SSM Parameter Store + Secrets; Security Group không inbound cho API và worker; review chéo quyền DynamoDB/SQS với backend. Xong khi: worker ghi vào bucket input bị AccessDenied như nghiệm thu. | G38: Bảo mật (ngang) | H38: IAM roles/policies, SSM Parameter Store, Security Groups | I38: G | J38: Lớp bảo mật cắt ngang mọi tầng: [5] bảng, [6] hàng đợi, [8] object, [9] quyền chuyển trạng thái, [12] mạng. Nguyên tắc 'worker không đọc secret, danh tính = instance profile' và 'code không phân nhánh theo môi trường' chỉ kiểm chứng được bằng IAM thật — local (test/test) không phát hiện quyền thừa. | K38: docs-worker/3 §3.9; docs-cloud/3 (bảng IAM identity/permission) | L38: 1–2 | M38: High | N38: 1.5 | O38: Nguyên | P38: Vũ, Phương (review quyền) | Q38: ❌ Chưa có policy nào trong repo (infra/terraform chưa có file .tf) | R38: Làm cùng A08: quyền sai chỉ lộ khi chạy AWS thật, sửa muộn sẽ chặn A09/A10 | S38: Progress 2 §3.2 dòng A06; docs-cloud/3; docs-worker/3 §3.9
A39: 36 | B39: A06.1 | C39: TASK | D39: Viết policy API role / Worker role / Deploy role | F39: Theo bảng phạm vi quyền docs-cloud/3 §6; dùng ARN/prefix, kiểm tra thêm quyền KMS nếu SecureString dùng CMK. | G39: Bảo mật | H39: IAM managed policies; instance profile EC2 | I39: G | J39: Tách ba danh tính phản ánh đúng ba đường đi trong kiến trúc: request nghiệp vụ (API), xử lý nền (worker), và thao tác vận hành (deploy) - deploy role không được admin toàn account. | K39: docs-cloud/3 §6 | L39: 1–2 | M39: High | O39: Nguyên | P39: Phương, Vũ | Q39: ❌ Chưa có | R39: Quyền ghi trạng thái vẫn phải nằm trong code, không chỉ dựa vào IAM | S39: docs-cloud/3 §6
A40: 37 | B40: A06.2 | C40: TASK | D40: SSM Parameter Store /tvc/{env}/... và SecureString tunnel token | F40: Các path đã có script dùng cứng: /tvc/{env}/worker/image-tag, /tvc/{env}/cloudflared/token; secret không nhúng image/user-data/output Terraform. | G40: Bảo mật + Vận hành | H40: SSM Parameter Store; deploy scripts | I40: G | J40: Là cầu nối cấu hình giữa hạ tầng và ứng dụng: App không hard-code ARN mà đọc tên/secret từ env/SSM do Cloud cấp, nhờ đó một codebase chạy cả local lẫn cloud. | K40: docs-cloud/3 §4, §6 | L40: 1–2 | M40: High | O40: Nguyên | P40: Lưu, Vũ | Q40: ❌ Chưa có | R40: Local có SSM trong compose nhưng chưa có luồng cấp secret tương ứng | S40: docs-cloud/3 §3, §6; docs-common/2
...

Sheet Cơ sở kế hoạch
A1: 3.1 CƠ SỞ KẾ HOẠCH + PHÂN BỔ THEO SPRINT
A2: 4 thành viên · 4 sprint (mỗi sprint 1 tuần) · 1 tuần dự phòng; 1 pd = một người làm việc tập trung trong một ngày. Cột Effort và các dòng Đối chiếu là công thức nối thẳng sang sheet 'Hạng mục công việc' — sửa effort ở đó thì các số này tự đổi.
A4: THÔNG SỐ KẾ HOẠCH
A5: Số thành viên | C5: 4 | D5: Bảng vai trò 3.1
A6: Số sprint | C6: 4 | D6: Mỗi sprint 1 tuần (tuần 7–10)
A7: Tuần dự phòng | C7: 1 | D7: Hoàn thiện báo cáo, sửa lỗi, chuẩn bị demo
A8: Days/người/tuần (dải) | C8: 2–3 ngày | D8: Cam kết của từng thành viên
A9: Capacity ước tính (dải, pd) | C9: 32–48 | D9: 4 người × 2–3 ngày × 4 tuần
A10: Capacity sử dụng theo kế hoạch (pd) | C10: 40 | D10: 4 × 2,5 ngày × 4 tuần
A12: BẢNG VAI TỪNG THÀNH VIÊN (capacity planning)
A13: Thành viên | B13: Viết tắt dùng trong bảng 3.2 | C13: Vai trò | D13: Capacity (pd) | E13: Trách nhiệm
A14: Bùi Hải Phương | B14: Phương | C14: Frontend, Backend | D14: 10 | E14: Backend, Developer API, giao diện SaaS
A15: Đào Lê Long Vũ | B15: Vũ | C15: Frontend, Backend | D15: 10 | E15: Backend, Worker, giao diện SaaS
A16: Nguyễn Hữu Lưu | B16: Lưu | C16: DevOps | D16: 10 | E16: Thiết lập các dịch vụ cloud
A17: Hồ Văn Tiến Nguyên | B17: Nguyên | C17: DevOps | D17: 10 | E17: Thiết lập các dịch vụ cloud
A18: Tổng capacity nhóm | D18: =SUM(D14:D17) | E18: 40 pd là mức kế hoạch (2,5 ngày/tuần/người × 4 tuần × 4 người); dải thực tế 32–48 pd
A20: TẢI THEO SPRINT — phân bổ 36 pd của 13 hạng mục
A21: Mã | B21: Hạng mục | C21: Ưu tiên | D21: Effort (pd) | E21: Sprint 1 | F21: Sprint 2 | G21: Sprint 3 | H21: Sprint 4 | I21: Dự phòng | J21: Σ phân bổ | K21: Đối chiếu | L21: Sprint ghi trong 3.2
A22: A01 | B22: Chốt kiến trúc và khung dự án | C22: High | D22: =SUMIFS('Hạng mục công việc'!$N$4:$N$94,'Hạng mục công việc'!$B$4:$B$94,"A01",'Hạng mục công việc'!$C$4:$C$94,"EPIC") | E22: 2 | J22: =SUM(E22:I22) | K22: =J22-D22 | L22: 1
A23: A02 | B23: Backend Auth, Project, Video | C23: High | D23: =SUMIFS('Hạng mục công việc'!$N$4:$N$94,'Hạng mục công việc'!$B$4:$B$94,"A02",'Hạng mục công việc'!$C$4:$C$94,"EPIC") | E23: 2.5 | F23: 2.5 | J23: =SUM(E23:I23) | K23: =J23-D23 | L23: 1–2
A24: A03 | B24: Upload và điều phối job | C24: High | D24: =SUMIFS('Hạng mục công việc'!$N$4:$N$94,'Hạng mục công việc'!$B$4:$B$94,"A03",'Hạng mục công việc'!$C$4:$C$94,"EPIC") | F24: 1.25 | G24: 1.25 | J24: =SUM(E24:I24) | K24: =J24-D24 | L24: 2–3
A25: A04 | B25: Hoàn thiện Worker pipeline | C25: High | D25: =SUMIFS('Hạng mục công việc'!$N$4:$N$94,'Hạng mục công việc'!$B$4:$B$94,"A04",'Hạng mục công việc'!$C$4:$C$94,"EPIC") | E25: 1.5 | F25: 1.5 | J25: =SUM(E25:I25) | K25: =J25-D25 | L25: 1–2
A26: A05 | B26: Xây dựng giao diện người dùng | C26: High | D26: =SUMIFS('Hạng mục công việc'!$N$4:$N$94,'Hạng mục công việc'!$B$4:$B$94,"A05",'Hạng mục công việc'!$C$4:$C$94,"EPIC") | F26: 2 | G26: 2 | J26: =SUM(E26:I26) | K26: =J26-D26 | L26: 2–3
A27: A06 | B27: IAM và bảo mật | C27: High | D27: =SUMIFS('Hạng mục công việc'!$N$4:$N$94,'Hạng mục công việc'!$B$4:$B$94,"A06",'Hạng mục công việc'!$C$4:$C$94,"EPIC") | E27: 0.75 | F27: 0.75 | J27: =SUM(E27:I27) | K27: =J27-D27 | L27: 1–2
A28: A07 | B28: Đóng gói Docker và stack local | C28: Medium | D28: =SUMIFS('Hạng mục công việc'!$N$4:$N$94,'Hạng mục công việc'!$B$4:$B$94,"A07",'Hạng mục công việc'!$C$4:$C$94,"EPIC") | E28: 0.75 | F28: 0.75 | J28: =SUM(E28:I28) | K28: =J28-D28 | L28: 1–2
A29: A08 | B29: Terraform hạ tầng dữ liệu | C29: High | D29: =SUMIFS('Hạng mục công việc'!$N$4:$N$94,'Hạng mục công việc'!$B$4:$B$94,"A08",'Hạng mục công việc'!$C$4:$C$94,"EPIC") | E29: 1.5 | F29: 1.5 | J29: =SUM(E29:I29) | K29: =J29-D29 | L29: 1–2
A30: A09 | B30: Compute và deploy | C30: High | D30: =SUMIFS('Hạng mục công việc'!$N$4:$N$94,'Hạng mục công việc'!$B$4:$B$94,"A09",'Hạng mục công việc'!$C$4:$C$94,"EPIC") | F30: 2 | G30: 2 | J30: =SUM(E30:I30) | K30: =J30-D30 | L30: 2–3
A31: A10 | B31: Kiểm thử E2E và tích hợp | C31: High | D31: =SUMIFS('Hạng mục công việc'!$N$4:$N$94,'Hạng mục công việc'!$B$4:$B$94,"A10",'Hạng mục công việc'!$C$4:$C$94,"EPIC") | G31: 1.5 | H31: 1.5 | J31: =SUM(E31:I31) | K31: =J31-D31 | L31: 3–4
A32: A11 | B32: Benchmark và chaos test | C32: Medium | D32: =SUMIFS('Hạng mục công việc'!$N$4:$N$94,'Hạng mục công việc'!$B$4:$B$94,"A11",'Hạng mục công việc'!$C$4:$C$94,"EPIC") | H32: 2 | J32: =SUM(E32:I32) | K32: =J32-D32 | L32: 4
A33: A12 | B33: Hỗ trợ kiểm thử E2E (worker, giao diện) | C33: Medium | D33: =SUMIFS('Hạng mục công việc'!$N$4:$N$94,'Hạng mục công việc'!$B$4:$B$94,"A12",'Hạng mục công việc'!$C$4:$C$94,"EPIC") | H33: 0.5 | J33: =SUM(E33:I33) | K33: =J33-D33 | L33: 4
A34: A13 | B34: Báo cáo và demo | C34: Medium | D34: =SUMIFS('Hạng mục công việc'!$N$4:$N$94,'Hạng mục công việc'!$B$4:$B$94,"A13",'Hạng mục công việc'!$C$4:$C$94,"EPIC") | E34: 0.8 | F34: 0.8 | G34: 0.8 | H34: 0.8 | I34: 0.8 | J34: =SUM(E34:I34) | K34: =J34-D34 | L34: 1–4 + dự phòng
A35: TỔNG | D35: =SUM(D22:D34) | E35: =SUM(E22:E34) | F35: =SUM(F22:F34) | G35: =SUM(G22:G34) | H35: =SUM(H22:H34) | I35: =SUM(I22:I34) | J35: =SUM(J22:J34) | K35: =SUM(K22:K34)
A36: Capacity mỗi sprint | E36: 10 | F36: 10 | G36: 10 | H36: 10 | I36: 12 | L36: Tuần dự phòng: 4 người × 3 ngày
A37: Chênh lệch (phân bổ − capacity) | E37: =E35-E36 | F37: =F35-F36 | G37: =G35-G36 | H37: =H35-H36 | I37: =I35-I36
A38: Tải so với capacity | E38: =E35/E36 | F38: =F35/F36 | G38: =G35/G36 | H38: =H35/H36 | I38: =I35/I36
A39: Giả định phân bổ: effort của hạng mục trải qua nhiều sprint được chia đều cho các sprint đó; A13 chia 0,8 pd cho mỗi sprint và tuần dự phòng; 'Cả nhóm' (A01, A13) chia đều 4 người. Các ô tô đỏ là sprint vượt capacity — xem sheet 'Mốc và phụ thuộc', khối 'ĐIỂM CẦN RÀ'. Số phân bổ theo sprint là giả định lập kế hoạch, chỉ cột Effort là số của bảng 3.2.
A42: CĂN CỨ ƯỚC LƯỢNG THEO HIỆN TRẠNG REPO (rà soát 27/10)
A43: Kết luận từ repo | G43: Ảnh hưởng lên kế hoạch
A44: Worker Go + FFmpeg đã chạy trọn pipeline local tới COMPLETED, có unit test — khoảng 75% đầu việc | G44: A04 giảm còn 3,0 pd; Vũ dồn phần dư sang A05 (giao diện)
A45: Backend Spring Boot chưa có dòng code nào (backend/ chỉ có README) | G45: A02 + A03 = 7,5 pd — hạng mục lớn nhất, đường găng của kế hoạch
...

Sheet Ánh xạ kiến trúc
A1: ÁNH XẠ KIẾN TRÚC — mỗi thành phần hệ thống ứng với hạng mục nào (A01–A13)
A2: Chiều ngược của bảng chính: ứng với mỗi thành phần trong kiến trúc, hạng mục nào chạm tới nó và nó đang ở trạng thái nào. Tham chiếu [n] của từng thành phần xem sheet 'Nguồn và quy ước'.
A3: Tầng kiến trúc | B3: Thành phần / dịch vụ | C3: Vị trí trong sơ đồ luồng | D3: Hạng mục công việc liên quan | E3: Hợp đồng / nguồn sự thật | F3: Trạng thái theo bằng chứng repo | G3: Ghi chú kỹ thuật / điểm mở
A4: Trình bày | B4: React SaaS Web (Vite + TypeScript + hls.js) | C4: Client → CloudFront / | D4: A05, A09 | E4: openapi.yaml; video-state-machine.md | F4: ❌ frontend/ chỉ có README | G4: Phát triển độc lập trên mock (MSW) rồi hợp nhất tuần 9; rủi ro mock drift
A5: Trình bày / Edge | B5: CloudFront default behavior → S3 frontend | C5: Người dùng → CloudFront / → bucket frontend | D5: A09 | E5: s3-key-convention.md (bucket frontend) | F5: ❌ Chưa có | G5: S3 REST origin + OAC; default root index.html; SPA fallback chỉ ở frontend
A6: Edge / Truy cập | B6: CloudFront /api/* → Cloudflare Tunnel → EC2 API | C6: Browser → CloudFront /api/* → origin-api.<domain> → cloudflared → 127.0.0.1:8080 | D6: A09, A02 | E6: openapi.yaml | F6: ❌ Chưa có | G6: Bắt buộc: origin request policy AllViewerExceptHostHeader (không forward Host viewer); CachingDisabled
A7: Edge / Phân phối | B7: CloudFront /media/* + Function rewrite → S3 output | C7: Người xem → /media/{projectId}/{videoId}/hls/master.m3u8 → rewrite → bucket output | D7: A09, A04, A05 | E7: s3-key-convention.md | F7: ❌ Chưa có | G7: Behavior không tự bỏ tiền tố /media; Content-Type .m3u8/.ts/.jpg phải đúng; TTL/invalidation khi xử lý lại
A8: Ứng dụng / API | B8: Spring Boot module A - Identity & Project | C8: JWT (SaaS) và API key (Developer API) → cùng một backend | D8: A02, A06 | E8: dynamodb-tables.md; openapi.yaml | F8: ❌ backend/ chỉ có README | G8: API key gắn project, chỉ lưu hash; ownership enforce ở đây chứ không ở IAM
A9: Ứng dụng / API | B9: Spring Boot module B - Video Management | C9: API → DynamoDB videos (GSI theo projectId) | D9: A02, A03 | E9: dynamodb-tables.md | F9: ❌ Chưa có | G9: Cursor pagination; trạng thái hiển thị theo state machine
A10: Ứng dụng / API | B10: Spring Boot module C - Upload Service | C10: API ký presigned PUT → browser PUT thẳng S3 input (không qua API) | D10: A03, A08, A07 | E10: upload-limits.md; s3-key-convention.md | F10: ❌ Chưa có | G10: Chuỗi bảo vệ giới hạn: client → API khai báo → confirm HeadObject → ffprobe → lifecycle
A11: Ứng dụng / API | B11: Spring Boot module D - Job Management | C11: API confirm → UPLOADING→PENDING → SendMessage SQS | D11: A03, A04 | E11: sqs-job-message.schema.json; video-state-machine.md | F11: ❌ Chưa có | G11: ĐIỂM MỞ: UpdateItem và SendMessage không nguyên tử → dễ mất job im lặng
A12: Ứng dụng / API | B12: Spring Boot module F - Asset & Integration | C12: GET /videos/{id} trả trạng thái + assets, API ghép /media/ | D12: A03, A05, P1-1 | E12: openapi.yaml | F12: ❌ Chưa có | G12: 'Một call cho trạng thái + asset'; lưu S3 key chứ không lưu URL đầy đủ
A13: Xử lý | B13: Worker Go + FFmpeg (module E) trong container tvc-worker | C13: SQS → worker → S3 input → ffprobe/FFmpeg → S3 output → DynamoDB → ACK | D13: A04, A09 | E13: docs-worker/3 §3.3-§3.9; s3-key-convention.md | F13: ✅ Code Go 1.427 dòng, COMPLETED trên LocalStack; ❌ chưa Dockerfile / chưa AWS | G13: Một job một lúc mỗi máy; muốn tăng throughput thì ASG thêm máy; không có nhánh code theo môi trường
A14: Xử lý / Dữ liệu | B14: SQS tvc-{env}-jobs + DLQ (maxReceiveCount 3) | C14: API → queue → worker; redrive → DLQ; backlog → metric → ASG | D14: A03, A04, A08, A11 | E14: sqs-job-message.schema.json | F14: ✅ LocalStack; ❌ AWS | G14: Visibility 300 s là khởi điểm, không phải deadline transcode
... A30: Kiểm chứng | B30: tests/e2e/ + benchmark harness (module H) | C30: Chạy cùng kịch bản với BASE_URL local và cloud | D30: A10, A11 | E30: docs-cloud/4 §5, §9 | F30: ❌ chỉ có README; make e2e/chaos là placeholder | G30: Không dùng kết quả placeholder làm bằng chứng nghiệm thu

Sheet Tải theo người
A1: TẢI ƯỚC TÍNH THEO NGƯỜI CHỊU TRÁCH NHIỆM
A2: Hàng 'Effort bảng 3.2' lấy bằng SUMIFS từ sheet 'Hạng mục công việc'; hàng 'Chênh lệch' phải bằng 0 với mọi cột. 'Cả nhóm' (A01, A13) chia đều 4 người.
A3: Thành viên | B3: Vai trò | C3: A01 | D3: A02 | E3: A03 | F3: A04 | G3: A05 | H3: A06 | I3: A07 | J3: A08 | K3: A09 | L3: A10 | M3: A11 | N3: A12 | O3: A13 | P3: Tổng (pd) | Q3: Capacity (pd) | R3: % tải
A4: Bùi Hải Phương | B4: Frontend, Backend | C4: 0.5 | D4: 5 | E4: 2.5 | O4: 1 | P4: =SUM(C4:O4) | Q4: 10 | R4: =P4/Q4
A5: Đào Lê Long Vũ | B5: Frontend, Backend | C5: 0.5 | F5: 3 | G5: 4 | N5: 0.5 | O5: 1 | P5: =SUM(C5:O5) | Q5: 10 | R5: =P5/Q5
A6: Nguyễn Hữu Lưu | B6: DevOps | C6: 0.5 | I6: 1.5 | J6: 3 | L6: 3 | O6: 1 | P6: =SUM(C6:O6) | Q6: 10 | R6: =P6/Q6
A7: Hồ Văn Tiến Nguyên | B7: DevOps | C7: 0.5 | H7: 1.5 | K7: 4 | M7: 2 | O7: 1 | P7: =SUM(C7:O7) | Q7: 10 | R7: =P7/Q7
A8: Tải theo người (Σ) | C8: =SUM(C4:C7) | D8: =SUM(D4:D7) | E8: =SUM(E4:E7) | F8: =SUM(F4:F7) | G8: =SUM(G4:G7) | H8: =SUM(H4:H7) | I8: =SUM(I4:I7) | J8: =SUM(J4:J7) | ... Q8: =SUM(Q4:Q7)
A9: Effort bảng 3.2 (SUMIFS) | C9: =SUMIFS('Hạng mục công việc'!$N$4:$N$94,'Hạng mục công việc'!$B$4:$B$94,"A01",'Hạng mục công việc'!$C$4:$C$94,"EPIC") | D9: =SUMIFS('Hạng mục công việc'!$N$4:$N$94,'Hạng mục công việc'!$B$4:$B$94,"A02",'Hạng mục công việc'!$C$4:$C$94,"EPIC") | E9: =SUMIFS('Hạng mục công việc'!$N$4:$N$94,'Hạng mục công việc'!$B$4:$B$94,"A03",'Hạng mục công việc'!$C$4:$C$94,"EPIC") | F9: =SUMIFS('Hạng mục công việc'!$N$4:$N$94,'Hạng mục công việc'!$B$4:$B$94,"A04",'Hạng mục công việc'!$C$4:$C$94,"EPIC") | G9: =SUMIFS('Hạng mục công việc'!$N$4:$N$94,'Hạng mục công việc'!$B$4:$B$94,"A05",'Hạng mục công việc'!$C$4:$C$94,"EPIC") | H9: =SUMIFS('Hạng mục công việc'!$N$4:$N$94,'Hạng mục công việc'!$B$4:$B$94,"A06",'Hạng mục công việc'!$C$4:$C$94,"EPIC") | I9: =SUMIFS('Hạng mục công việc'!$N$4:$N$94,'Hạng mục công việc'!$B$4:$B$94,"A07",'Hạng mục công việc'!$C$4:$C$94,"EPIC") | J9: =SUMIFS('Hạng mục công việc'!$N$4:$N$94,'Hạng mục công việc'!$B$4:$B$94,"A08",'Hạng mục công việc'!$C$4:$C$94,"EPIC") | K9: =SUMIFS('Hạng mục công việc'!$N$4:$N$94,'Hạng mục công việc'!$B$4:$B$94,"A09",'Hạng mục công việc'!$C$4:$C$94,"EPIC") | L9: =SUMIFS('Hạng mục công việc'!$N$4:$N$94,'Hạng mục công việc'!$B$4:$B$94,"A10",'Hạng mục công việc'!$C$4:$C$94,"EPIC") | M9: =SUMIFS('Hạng mục công việc'!$N$4:$N$94,'Hạng mục công việc'!$B$4:$B$94,"A11",'Hạng mục công việc'!$C$4:$C$94,"EPIC") | N9: =SUMIFS('Hạng mục công việc'!$N$4:$N$94,'Hạng mục công việc'!$B$4:$B$94,"A12",'Hạng mục công việc'!$C$4:$C$94,"EPIC") | O9: =SUMIFS('Hạng mục công việc'!$N$4:$N$94,'Hạng mục công việc'!$B$4:$B$94,"A13",'Hạng mục công việc'!$C$4:$C$94,"EPIC") | P9: =SUMIFS('Hạng mục công việc'!$N$4:$N$94,'Hạng mục công việc'!$C$4:$C$94,"EPIC")
A10: Chênh lệch (phải bằng 0) | C10: =C8-C9 | D10: =D8-D9 | E10: =E8-E9 | F10: =F8-F9 | G10: =G8-G9 | H10: =H8-H9 | I10: =I8-I9 | J10: =J8-J9 | ... P10: =P8-P9
A12: P1 / tùy chọn không cộng vào tổng: Webhook 1,5 pd (Phương), CI/CD hoàn chỉnh + Terraform phần còn lại 1,5 pd (Nguyên), metricpub 0,5 pd (Nguyên) — tổng 3,5 pd.
A13: Ghi chú rà tải: mỗi người đúng 9,0/10,0 pd (90%) — cân bằng nhưng không còn dư cho rủi ro riêng của cá nhân; Phương gánh đường găng A02+A03 nên cần Vũ san phần review/hợp đồng khi chậm.
A14: Quy chiếu tên: Bùi Hải Phương = Phương · Đào Lê Long Vũ = Vũ · Nguyễn Hữu Lưu = Lưu · Hồ Văn Tiến Nguyên = Nguyên.

Sheet Mốc và phụ thuộc
A1: MỐC THEO SPRINT, ĐƯỜNG GĂNG, THỨ TỰ CẮT GIẢM VÀ ĐIỂM CẦN RÀ
A2: Không coi mốc đã qua là đã hoàn thành nếu chưa có bằng chứng. Tuần dự phòng không phải tuần phát triển bù.
A4: MỐC NGHIỆM THU THEO SPRINT (M0–M5 quy chiếu sang sprint)
A5: Mốc | B5: Thời điểm | C5: Tiêu chí nghiệm thu | D5: Hạng mục mở khóa | E5: Bằng chứng cần có | F5: Nếu trễ
A6: Cuối sprint 1 | B6: Cuối tuần 7 | C6: Hợp đồng hết DRAFT; khung backend/ + worker/ build & test được; make infra/smoke đạt ≥2 máy; Dockerfile tồn tại. | D6: A01, A07, A08 (khởi động), A04 (ghép docker) | E6: PR contract được 4 người approve; log smoke; `go test ./...` xanh; `docker build` hai image | F6: Dồn vào A01 + Dockerfile; backend có thể bắt đầu trên nháp nhưng phải ghi rõ giả định
A7: Cuối sprint 2 = M2 | B7: Cuối tuần 8 (điểm kiểm soát bắt buộc) | C7: Pipeline end-to-end trên AWS: upload → SQS → worker → HLS → COMPLETED; S3/SQS/DynamoDB do Terraform tạo; IAM worker chạy thật, quyền thừa bị từ chối. | D7: A02, A03, A04, A06, A08, A09 (một phần) | E7: videoId + jobId + trạng thái + danh sách output + log không secret trên môi trường thật | F7: Không dời hạn tuần 10: dồn nguồn lực vào luồng chính, KHÔNG mở P1, lấy bằng chứng tối thiểu
A8: Cuối sprint 3 = M3 | B8: Cuối tuần 9 | C8: SaaS + Developer API + HLS chạy cùng origin qua CloudFront + Tunnel; player phát video thật; UI polling; giám sát/co giãn đã lắp đặt xong. | D8: A05, A09, A11 (phần lắp đặt) | E8: URL demo, screenshot 3 behavior, dashboard backlog, worker tự scale 1→2 | F8: Cắt trang embed / tên miền riêng; giữ player + link streaming
A9: Cuối sprint 4 = M4 | B9: Cuối tuần 10 | C9: E2E đạt; số liệu benchmark 1 vs 2 worker + chaos/DLQ; báo cáo đủ ba phần; hai lần diễn tập; đóng băng phiên bản. | D9: A10, A11, A12, A13 | E9: Bảng số liệu + biểu đồ, kịch bản e2e chạy lại được, tag phiên bản đóng băng | F9: Benchmark rút còn 1 vs 2 worker; chaos local + 1 ca AWS; không thêm tính năng mới
A10: Tuần dự phòng = M5 | B10: Sau sprint 4 | C10: Rà hướng dẫn nộp, liên kết, phiên bản; chỉ sửa lỗi chặn nộp/demo. | D10: A13 | E10: Hồ sơ nộp + xác nhận nộp được lưu | F10: Đây là tuần đệm, không phải tuần phát triển bù — nếu phải dùng chứng tỏ kế hoạch sai từ sprint 2
A12: ĐƯỜNG GĂNG — thứ tự bắt buộc
A13: → A01 hợp đồng + khung → gate của mọi nhánh
A14: → A07 Docker → A08 Terraform dữ liệu → A06 IAM → A09 compute & deploy (chuỗi Cloud)
A15: → A02 backend → A03 upload/điều phối → A05 UI (chuỗi App)
A16: → A04 worker hoàn thiện (heartbeat/DLQ/chaos) → A10 e2e → A11 benchmark/chaos
A17: → A10 + A11 số liệu → A13 báo cáo & demo
A19: THỨ TỰ CẮT GIẢM KHI TRỄ (lever)
A20: # | B20: Lever | C20: Tiết kiệm | D20: Đổi lại
A21: 1 | B21: Bỏ metricpub, chốt ASG Min ≥ 1 + metric math | C21: 0,5 pd | D21: Tốn ~1 máy/đêm; demo vẫn scale 1→2 được
A22: 2 | B22: Bỏ tên miền riêng, dùng *.cloudfront.net | C22: ~0,5 pd | D22: Dòng A10/A11 rẻ hơn rõ rệt
A23: 3 | B23: Bỏ trang embed/mã nhúng, giữ player + link streaming | C23: ~0,5 pd | D23: Vẫn đủ luồng demo cốt lõi; ghi chú P1 trong báo cáo
A24: 4 | B24: Benchmark chỉ 1 vs 2 worker; chaos local + 1 ca AWS | C24: ~1,0 pd | D24: Vẫn đủ hai thí nghiệm bắt buộc
A25: 5 | B25: KHÔNG cắt được: A02, A03 (backend) | C25: — | D25: Không có backend thì e2e, demo và số liệu thực nghiệm đều vô nghĩa
A27: ĐIỂM CẦN RÀ TRONG BẢN KẾ HOẠCH NÀY (6 điểm)
A28: Vấn đề | C28: Vị trí trong workbook
A29: Tải sprint 2 vượt capacity | C29: Phân bổ đều theo sprint của bảng 3.2 cho Sprint 2 ≈ 13,05 pd trong khi capacity mỗi sprint là 10 pd (4 người × 2,5 ngày). Nên dời A08 (C1.5 network, C1.6 root envs) hoặc phần edge của A09 sang sprint 3. | F29: Xem sheet 'Cơ sở kế hoạch', khối 'TẢI THEO SPRINT'
A30: A09 chỉ ghi [11], [12] | C30: Bản trước là 'Compute, edge & deploy' với [1],[2],[3],[10],[11],[12]. Phần edge (CloudFront 3 behavior, Tunnel, OAC) vẫn là việc thật và vẫn nằm trong A09 — nên ghi đủ kẻo bị hiểu là đã cắt. | F30: Dòng A09, cột 'Phụ thuộc / rủi ro'
A31: A07 để Medium nhưng là blocker | C31: Không có Dockerfile thì A04 không ghép make up, A10 không có môi trường. Đề xuất đổi High và xếp làm sớm nhất (đúng ghi chú §3.3). | F31: Dòng A07
A32: Không còn hạng mục giám sát & co giãn riêng | C32: Bản 11 dòng có mục riêng; bản A01–A13 dồn vào A11 (Medium, sprint 4). Phần *lắp đặt* alarm/dashboard/scaling nên về cuối sprint 3 cùng A09, sprint 4 chỉ chạy thí nghiệm. | F32: Dòng A11 và mốc 'Cuối sprint 3'
A33: Tham chiếu [n] không kiểm chứng được trong repo | C33: [n] là STT bảng 15 giao diện ở mục kiến trúc triển khai (Hình 2.1 [1]–[10], Hình 2.2 [11]–[15]) nằm trong transvidcloud_report2_deployment_section_v2.tex — file này chưa có trong repo. Bảng '[n] ↔ thành phần' trong sheet 'Nguồn và quy ước' là suy đoán theo luồng, cần đối chiếu lại với bản vẽ gốc. | F33: Sheet 'Nguồn và quy ước'
A34: Tổng 36 pd = 90% capacity 40 pd | C34: Đệm chỉ còn ~4 pd so với ~8 pd của bản 32 pd; mỗi người đúng 9,0/10,0 pd. Cân đối tải là tốt nhưng không còn dư cho rủi ro backend (A02) — theo dõi A02 hằng tuần. | F34: Sheet 'Tải theo người'

Sheet Nguồn và quy ước
A1: NGUỒN TÀI LIỆU, QUY ƯỚC, BẢNG [n] VÀ GIẢ ĐỊNH
A3: QUY ƯỚC TRONG BẢNG
A4: ✅ | B4: Đã hoàn thành và có bằng chứng chạy được ghi trong tài liệu work/
A5: ⭕ | B5: Đang làm / có khung / DRAFT / chưa nối end-to-end
A6: ❌ | B6: Chưa có trong repo hoặc chỉ là placeholder
A7: ⚪ | B7: Chưa tới hạn hoặc ngoài cam kết nộp
A8: ⛔ | B8: Ngoài cam kết nộp tuần 10 (P1)
A9: pd | B9: Person-day = ngày công, KHÔNG phải số ngày lịch
A10: P0 / P1 | B10: P0 = cốt lõi thuộc cam kết nộp; P1 = nâng cao, ngoài cam kết
A11: Trống ở cột 'Còn lại (pd)' | B11: Chưa ước lượng lại: baseline vẫn là con số điều hành. Chỉ điền số khi tài liệu trong repo nêu rõ (A4, A5, A6, A5.5)
A12: Module chức năng | B12: A Identity & Project · B Video Management · C Upload Service · D Job Management · E Worker/Transcoding · F Asset & Integration · G Cloud/DevOps · H Benchmarking (SRS §26)
A13: EPIC / TASK / P1 | B13: EPIC = 13 hạng mục của bảng 3.2; TASK = nhiệm vụ chi tiết bóc ra; P1 = tùy chọn ngoài tổng effort
A14: High / Medium / Low | B14: High = bắt buộc trên đường găng (P0); Medium = nên làm nếu còn capacity; Low = P1 ngoài cam kết nộp
A15: [n] | B15: STT giao diện trong bảng 15 giao diện của mục kiến trúc triển khai (Hình 2.1: [1]–[10]; Hình 2.2: [11]–[15])
A16: Effort để trống ở dòng TASK | B16: Effort chỉ tính một lần ở cấp hạng mục; nhiệm vụ chi tiết dùng để theo dõi tiến độ, không cộng thêm pd
A18: BẢNG 15 GIAO DIỆN [n] — suy chiếu theo luồng hệ thống
A19: Bảng 3.2 tham chiếu [n] theo mục kiến trúc triển khai (transvidcloud_report2_deployment_section_v2.tex) — file này CHƯA có trong repo, nên bảng dưới là suy chiếu từ luồng hệ thống trong docs-common và docs-cloud. Cần đối chiếu lại với bản vẽ gốc trước khi nộp.
A22: [n] | B22: Tầng | C22: Thành phần / giao diện
A23: [1] | B23: Trình bày | C23: React SaaS Web qua CloudFront default behavior → bucket frontend
A24: [2] | B24: Truy cập | C24: CloudFront /api/* → Cloudflare Tunnel → EC2 API (Spring Boot)
A25: [3] | B25: Truy cập | C25: Developer API cùng origin /api/* — khác lớp xác thực (API key)
A26: [4] | B26: Dữ liệu | C26: Presigned PUT/PART từ client thẳng vào S3 input
A27: [5] | B27: Dữ liệu | C27: DynamoDB 4 bảng (users/projects/apikeys/videos) — nguồn sự thật metadata + state
A28: [6] | B28: Xử lý | C28: SQS jobs (+DLQ) nối API với worker, visibility 300s
A29: [7] | B29: Xử lý | C29: Worker Go + FFmpeg trên EC2 ASG (Spot) — decode một lần, 2 rendition
A30: [8] | B30: Dữ liệu | C30: S3 output {projectId}/{videoId}/hls + thumb, Content-Type đúng
A31: [9] | B31: Ngang | C31: Máy trạng thái UPLOADING→PENDING→PROCESSING→COMPLETED/FAILED_* (ghi có điều kiện)
A32: [10] | B32: Phân phối | C32: CloudFront /media/* + Function rewrite → HLS cho player và embed
A33: [11] | B33: Vận hành | C33: Đường deploy: build image → ECR → SSM image-tag → ASG rollover / GitHub Actions
... A37: [15] | B37: Thực nghiệm | C37: k6 / dataset mẫu phục vụ benchmark và chaos
A39: NGUỒN TRONG REPO
A40: docs/introduction/1. Timelines.md | B40: Nguồn chính: 16 epic, effort pd, chủ nhiệm, sprint, ưu tiên; phân vai; quyết định MVP; điểm đồng bộ; M0-M5; thứ tự cắt giảm; rủi ro kỹ thuật 8.1-8.5
A41: docs/introduction/3. SRS highlevel.md | B41: Module chức năng A-H (§26), các tầng kiến trúc (§9.1), priority P0/P1/P2 và ma trận dịch vụ (§19), ràng buộc ⛔
A42: docs/docs-common/1. Overall system.md | B42: Sơ đồ thành phần logical, luồng nghiệp vụ 8 bước, bảng local vs AWS, quyền sở hữu thư mục/repo, phạm vi MVP
A43: docs/docs-common/2. Implementation status.md | B43: Trạng thái thật của từng thành phần trong repo (rà soát 21/10/2026) và Definition of Done kỹ thuật P0
A44: docs/docs-common/3. Contracts and boundaries.md | B44: Bản đồ hợp đồng, ranh giới App/Cloud, bảng ai được ghi gì vào DynamoDB, quy trình đổi contract
A45: docs/docs-common/4. Timelines.md | B45: Bốn sprint, bàn giao App↔Cloud, M0-M5 rút gọn, việc ngoài đường găng
A46: docs/docs-common/5. Architecture decisions.md | B46: ADR 0001 - DynamoDB only (bối cảnh, quyết định, hệ quả)
A47: docs/docs-cloud/2. Timelines.md | B47: Lịch theo sprint cho Lưu/Nguyên, checklist bằng chứng M0-M5, bảng effort C0-C6 và phân tích capacity
A48: docs/docs-cloud/3. Designs.md | B48: Kiến trúc hạ tầng: mermaid tổng thể, tổ chức Terraform module, S3/DynamoDB/queue, IAM theo danh tính, CloudFront/Tunnel/HLS, compute & Spot, quan sát, điểm cần chốt
...
